Workbook

Sheet Approved_KRIS
A1: APPROVED by KRIS
A3: Item | B3: Cost (Rs) | C3: Notes
A4: Creative Direction
A5: Creative Direction & Event Concept | B5: =Revenue!I2 -> 300000
A6: Design
A7: Logo Design | B7: =Revenue!I3 -> 90000
A8: Derivatives- Flyer/Pattern/BG | B8: =Revenue!I4 -> 70000
A9: Stage & Content
A10: CEO Keynote Presentation Design (incl. 100+ slides, graphics, storytelling) | B10: =Revenue!I5 -> 275000
A11: Speaker Presentations (x3) | B11: =Revenue!I6 -> 90000
A12: Screen / LED Content Management | B12: =Revenue!I7 -> 70000
A13: Sustenance
A14: Sustenance- Food, Drink, Fuel | B14: =Revenue!I8 -> 120000
A15: Visual Team (Talent Overseas) WOW Effect
A16: Backdrop Animation | B16: =Revenue!I9 -> 100000
A17: Walk-in & Ambience Music | B17: =Revenue!I10 -> 100000
A18: Content Capture
A19: Video Coverage (2-cam setup + edits) + BTS + Same day Edit | B19: =Revenue!I11 -> 220000
A20: Photography | B20: 100000
A21: Management & Coordination
A22: Santral Art/Nico | C22: TBC / not priced
A24: Summary
A25: Subtotal | B25: =SUM(B5:B20) -> 1535000
A26: DISCOUNT | B26: 80000
A27: Subtotal - Discount | B27: =B25-B26 -> 1455000
A28: Agency Fee (10%) | B28: =B27*0.1 -> 145500
A29: Subtotal + Agency | B29: =B28+B27 -> 1600500
A30: VAT (15%) | B30: =B29*0.15 -> 240075
A31: TOTAL ESTIMATE | B31: =B30+B29 -> 1840575

Sheet Lists
A1: Categories | C1: Expense Types | E1: Paid By | G1: Invoice Status | I1: Cash Status
A2: Creative Direction | C2: Freelance | E2: ë | G2: Draft | I2: Owed
A3: Design | C3: Supplier | E3: Avneesh | G3: Invoiced | I3: Reimbursed
A4: Video | C4: Cash | E4: Long | G4: Part-paid | I4: Settled/Net-off
A5: Tech/AV | C5: Card | E5: Williams | G5: Paid
A6: Scenography | C6: Bank Transfer | E6: Laura
A7: Sound Design | C7: Internal Allocation | E7: Other
A8: Travel | C8: Other | E8: Harsh
A9: Food | E9: Kunal
A10: Transport | E10: Petty Cash
A11: Accommodation
A12: Printing
A13: Rentals
A14: Marketing/PR
A15: Admin
A16: Other
A17: Production
A18: Photography

Sheet Revenue
A1: Date Approved | B1: Project | C1: Client | D1: Item Code | E1: Item Description | F1: Category | G1: Qty | H1: Unit Price (Rs) | I1: Line Total (Rs) | J1: Approved By | K1: Invoice Status | L1: Invoice # | M1: Paid Date | N1: Notes
B2: Mauritius Telecom Connect | C2: Mauritius Telecom | D2: MT-CON-01 | E2: Creative Direction & Event Concept | F2: Creative Direction | G2: 1 | H2: 300000 | I2: =IF(OR(G2="",H2=""),"",G2*H2) -> 300000 | J2: KRIS | K2: Draft
B3: Mauritius Telecom Connect | C3: Mauritius Telecom | D3: MT-CON-02 | E3: Logo Design | F3: Design | G3: 1 | H3: 90000 | I3: =IF(OR(G3="",H3=""),"",G3*H3) -> 90000 | J3: KRIS | K3: Draft
B4: Mauritius Telecom Connect | C4: Mauritius Telecom | D4: MT-CON-03 | E4: Derivatives- Flyer/Pattern/BG | F4: Design | G4: 1 | H4: 70000 | I4: =IF(OR(G4="",H4=""),"",G4*H4) -> 70000 | J4: KRIS | K4: Draft
B5: Mauritius Telecom Connect | C5: Mauritius Telecom | D5: MT-CON-04 | E5: CEO Keynote Presentation Design (incl. 100+ slides, graphics, storytelling) | F5: Design | G5: 1 | H5: 275000 | I5: =IF(OR(G5="",H5=""),"",G5*H5) -> 275000 | J5: KRIS | K5: Draft
B6: Mauritius Telecom Connect | C6: Mauritius Telecom | D6: MT-CON-05 | E6: Speaker Presentations (x3) | F6: Design | G6: 1 | H6: 90000 | I6: =IF(OR(G6="",H6=""),"",G6*H6) -> 90000 | J6: KRIS | K6: Draft
B7: Mauritius Telecom Connect | C7: Mauritius Telecom | D7: MT-CON-06 | E7: Screen / LED Content Management | F7: Tech/AV | G7: 1 | H7: 70000 | I7: =IF(OR(G7="",H7=""),"",G7*H7) -> 70000 | J7: KRIS | K7: Draft
B8: Mauritius Telecom Connect | C8: Mauritius Telecom | D8: MT-CON-07 | E8: Sustenance- Food, Drink, Fuel | F8: Food | G8: 1 | H8: 120000 | I8: =IF(OR(G8="",H8=""),"",G8*H8) -> 120000 | J8: KRIS | K8: Draft
B9: Mauritius Telecom Connect | C9: Mauritius Telecom | D9: MT-CON-08 | E9: Backdrop Animation | F9: Video | G9: 1 | H9: 100000 | I9: =IF(OR(G9="",H9=""),"",G9*H9) -> 100000 | J9: KRIS | K9: Draft
B10: Mauritius Telecom Connect | C10: Mauritius Telecom | D10: MT-CON-09 | E10: Walk-in & Ambience Music | F10: Production | G10: 1 | H10: 100000 | I10: =IF(OR(G10="",H10=""),"",G10*H10) -> 100000 | J10: KRIS | K10: Draft
B11: Mauritius Telecom Connect | C11: Mauritius Telecom | D11: MT-CON-10 | E11: Video Coverage (2-cam setup + edits) + BTS + Same day Edit | F11: Video | G11: 1 | H11: 220000 | I11: =IF(OR(G11="",H11=""),"",G11*H11) -> 220000 | J11: KRIS | K11: Draft
B12: Mauritius Telecom Connect | C12: Mauritius Telecom | D12: MT-CON-11 | E12: Photography | F12: Photography | G12: 1 | H12: 100000 | I12: =IF(OR(G12="",H12=""),"",G12*H12) -> 100000 | J12: KRIS | K12: Draft
G13: 1 | I13: =IF(OR(G13="",H13=""),"",G13*H13)
A14: TOTAL | G14: 1 | I14: =IF(OR(G14="",H14=""),"",G14*H14)
G15: 1 | I15: =IF(OR(G15="",H15=""),"",G15*H15)
G16: 1 | I16: =IF(OR(G16="",H16=""),"",G16*H16)
G17: 1 | I17: =IF(OR(G17="",H17=""),"",G17*H17)
G18: 1 | I18: =IF(OR(G18="",H18=""),"",G18*H18)
G19: 1 | I19: =IF(OR(G19="",H19=""),"",G19*H19)
G20: 1 | I20: =IF(OR(G20="",H20=""),"",G20*H20)
G21: 1 | I21: =IF(OR(G21="",H21=""),"",G21*H21)
G22: 1 | I22: =IF(OR(G22="",H22=""),"",G22*H22)
G23: 1 | I23: =IF(OR(G23="",H23=""),"",G23*H23)
G24: 1 | I24: =IF(OR(G24="",H24=""),"",G24*H24)
G25: 1 | I25: =IF(OR(G25="",H25=""),"",G25*H25)
G26: 1 | I26: =IF(OR(G26="",H26=""),"",G26*H26)
... G32: 1 | I32: =IF(OR(G32="",H32=""),"",G32*H32)

Sheet Expenses
A1: Date | B1: Project | C1: Description | D1: Category | E1: Supplier/Person | F1: Expense Type | G1: Amount (Rs) | H1: Paid By | I1: VAT Applicable | J1: VAT Rate | K1: VAT Amount (Rs) | L1: Total excl VAT (Rs) | M1: Receipt (Y/N) | N1: Accounting Status | O1: Reference/Receipt # | P1: Notes
B2: Mauritius Telecom Connect | C2: Video | D2: Video | E2: Neil VIDEO | F2: Freelance | G2: 205000 | H2: ë | I2: No | K2: =IF(OR(G2="",I2=""),"",IF(UPPER(I2)="YES",G2*J2,0)) -> 0 | L2: =IF(G2="","",G2+K2) -> 205000 | N2: Pending
B3: Mauritius Telecom Connect | C3: Creative Direction | D3: Creative Direction | E3: David | F3: Internal Allocation | G3: 50000 | H3: ë | I3: No | K3: =IF(OR(G3="",I3=""),"",IF(UPPER(I3)="YES",G3*J3,0)) -> 0 | L3: =IF(G3="","",G3+K3) -> 50000 | N3: Pending
B4: Mauritius Telecom Connect | C4: Creative Direction | D4: Creative Direction | E4: Kunal | F4: Internal Allocation | G4: 119000 | H4: ë | I4: No | K4: =IF(OR(G4="",I4=""),"",IF(UPPER(I4)="YES",G4*J4,0)) -> 0 | L4: =IF(G4="","",G4+K4) -> 119000 | N4: Pending
B5: Mauritius Telecom Connect | C5: Design | D5: Design | E5: Harsh | F5: Freelance | G5: 120000 | H5: ë | I5: No | K5: =IF(OR(G5="",I5=""),"",IF(UPPER(I5)="YES",G5*J5,0)) -> 0 | L5: =IF(G5="","",G5+K5) -> 120000 | N5: Pending
B6: Mauritius Telecom Connect | C6: Video | D6: Video | E6: Dopeman | F6: Freelance | G6: 50000 | H6: ë | I6: No | K6: =IF(OR(G6="",I6=""),"",IF(UPPER(I6)="YES",G6*J6,0)) -> 0 | L6: =IF(G6="","",G6+K6) -> 50000 | N6: Pending
B7: Mauritius Telecom Connect | C7: Other | D7: Other | E7: Others | F7: Supplier | G7: 24500 | H7: ë | I7: No | K7: =IF(OR(G7="",I7=""),"",IF(UPPER(I7)="YES",G7*J7,0)) -> 0 | L7: =IF(G7="","",G7+K7) -> 24500 | N7: Pending
B8: Mauritius Telecom Connect | C8: Creative Direction | D8: Creative Direction | E8: Avneesh | F8: Internal Allocation | G8: 180000 | H8: ë | I8: No | K8: =IF(OR(G8="",I8=""),"",IF(UPPER(I8)="YES",G8*J8,0)) -> 0 | L8: =IF(G8="","",G8+K8) -> 180000 | N8: Pending
B9: Mauritius Telecom Connect | C9: Production | D9: Production | E9: Kevin | F9: Freelance | G9: 70000 | H9: ë | I9: No | K9: =IF(OR(G9="",I9=""),"",IF(UPPER(I9)="YES",G9*J9,0)) -> 0 | L9: =IF(G9="","",G9+K9) -> 70000 | N9: Pending
B10: Mauritius Telecom Connect | C10: Video | D10: Video | E10: Lakshraj – Video Trade Route | F10: Freelance | G10: 10000 | H10: ë | I10: No | K10: =IF(OR(G10="",I10=""),"",IF(UPPER(I10)="YES",G10*J10,0)) -> 0 | L10: =IF(G10="","",G10+K10) -> 10000 | N10: Pending
B11: Mauritius Telecom Connect | C11: Video | D11: Video | E11: Gloria | F11: Freelance | G11: 20000 | H11: ë | I11: No | K11: =IF(OR(G11="",I11=""),"",IF(UPPER(I11)="YES",G11*J11,0)) -> 0 | L11: =IF(G11="","",G11+K11) -> 20000 | N11: Pending
B12: Mauritius Telecom Connect | C12: Admin | D12: Admin | E12: Store | F12: Supplier | G12: 25000 | H12: ë | I12: No | K12: =IF(OR(G12="",I12=""),"",IF(UPPER(I12)="YES",G12*J12,0)) -> 0 | L12: =IF(G12="","",G12+K12) -> 25000 | N12: Pending
A13: 45977 | B13: Mauritius Telecom Connect | C13: Pizza + Menwar team at studio | D13: Food | E13: Petty Cash | F13: Cash | G13: 385 | H13: Petty Cash | I13: Yes | J13: 0.15 | K13: =IF(OR(G13="",I13=""),"",IF(UPPER(I13)="YES",G13*J13,0)) -> 57.75 | L13: =IF(G13="","",G13-K13) -> 327.25 | N13: Pending | P13: Source: Petty Cash OUT list
A14: 45977 | B14: Mauritius Telecom Connect | C14: Millions Burger | D14: Food | E14: Petty Cash | F14: Cash | G14: 7000 | H14: Petty Cash | I14: Yes | J14: 0.15 | K14: =IF(OR(G14="",I14=""),"",IF(UPPER(I14)="YES",G14*J14,0)) -> 1050 | L14: =IF(G14="","",G14-K14) -> 5950 | N14: Pending | P14: Source: Petty Cash OUT list
A15: 45977 | B15: Mauritius Telecom Connect | C15: Others | D15: Other | E15: Petty Cash | F15: Cash | G15: 750 | H15: Petty Cash | I15: No | K15: =IF(OR(G15="",I15=""),"",IF(UPPER(I15)="YES",G15*J15,0)) -> 0 | L15: =IF(G15="","",G15+K15) -> 750 | N15: Pending | P15: Source: Petty Cash OUT list
A16: 45978 | B16: Mauritius Telecom Connect | C16: Millions Burger | D16: Food | E16: Petty Cash | F16: Cash | G16: 1446 | H16: Petty Cash | I16: Yes | J16: 0.15 | K16: =IF(OR(G16="",I16=""),"",IF(UPPER(I16)="YES",G16*J16,0)) -> 216.9 | L16: =IF(G16="","",G16-K16) -> 1229.1 | N16: Pending | P16: Source: Petty Cash OUT list
A17: 45985 | B17: Mauritius Telecom Connect | C17: Food | D17: Food | E17: Petty Cash | F17: Cash | G17: 3500 | H17: Petty Cash | I17: Yes | J17: 0.15 | K17: =IF(OR(G17="",I17=""),"",IF(UPPER(I17)="YES",G17*J17,0)) -> 525 | L17: =IF(G17="","",G17-K17) -> 2975 | N17: Pending | P17: Source: Petty Cash OUT list
A18: 45986 | B18: Mauritius Telecom Connect | C18: Gato | D18: Food | E18: Petty Cash | F18: Cash | G18: 500 | H18: Petty Cash | I18: Yes | J18: 0.15 | K18: =IF(OR(G18="",I18=""),"",IF(UPPER(I18)="YES",G18*J18,0)) -> 75 | L18: =IF(G18="","",G18-K18) -> 425 | N18: Pending | P18: Source: Petty Cash OUT list
A19: 45986 | B19: Mauritius Telecom Connect | C19: Carnet | D19: Other | E19: Petty Cash | F19: Cash | G19: 400 | H19: Petty Cash | I19: No | K19: =IF(OR(G19="",I19=""),"",IF(UPPER(I19)="YES",G19*J19,0)) -> 0 | L19: =IF(G19="","",G19+K19) -> 400 | N19: Pending | P19: Source: Petty Cash OUT list
A20: 45986 | B20: Mauritius Telecom Connect | C20: Harsh | D20: Other | E20: Petty Cash | F20: Cash | G20: 2960.5 | H20: Petty Cash | I20: No | K20: =IF(OR(G20="",I20=""),"",IF(UPPER(I20)="YES",G20*J20,0)) -> 0 | L20: =IF(G20="","",G20+K20) -> 2960.5 | N20: Pending | P20: Source: Petty Cash OUT list
A21: 45986 | B21: Mauritius Telecom Connect | C21: Food | D21: Food | E21: Petty Cash | F21: Cash | G21: 170 | H21: Petty Cash | I21: Yes | J21: 0.15 | K21: =IF(OR(G21="",I21=""),"",IF(UPPER(I21)="YES",G21*J21,0)) -> 25.5 | L21: =IF(G21="","",G21-K21) -> 144.5 | N21: Pending | P21: Source: Petty Cash OUT list
A22: 45987 | B22: Mauritius Telecom Connect | C22: Food | D22: Food | E22: Petty Cash | F22: Cash | G22: 1446 | H22: Petty Cash | I22: Yes | J22: 0.15 | K22: =IF(OR(G22="",I22=""),"",IF(UPPER(I22)="YES",G22*J22,0)) -> 216.9 | L22: =IF(G22="","",G22-K22) -> 1229.1 | N22: Pending | P22: Source: Petty Cash OUT list
A23: 45987 | B23: Mauritius Telecom Connect | C23: refund harsh food | D23: Food | E23: Petty Cash | F23: Cash | G23: 2755 | H23: Petty Cash | I23: Yes | J23: 0.15 | K23: =IF(OR(G23="",I23=""),"",IF(UPPER(I23)="YES",G23*J23,0)) -> 413.25 | L23: =IF(G23="","",G23-K23) -> 2341.75 | N23: Pending | P23: Source: Petty Cash OUT list
A24: 45987 | B24: Mauritius Telecom Connect | C24: Food | D24: Food | E24: Petty Cash | F24: Cash | G24: 485 | H24: Petty Cash | I24: Yes | J24: 0.15 | K24: =IF(OR(G24="",I24=""),"",IF(UPPER(I24)="YES",G24*J24,0)) -> 72.75 | L24: =IF(G24="","",G24-K24) -> 412.25 | N24: Pending | P24: Source: Petty Cash OUT list
A25: 45988 | B25: Mauritius Telecom Connect | C25: Other | D25: Other | E25: Petty Cash | F25: Cash | G25: 4000 | H25: Petty Cash | I25: No | K25: =IF(OR(G25="",I25=""),"",IF(UPPER(I25)="YES",G25*J25,0)) -> 0 | L25: =IF(G25="","",G25+K25) -> 4000 | N25: Pending | P25: Source: Petty Cash OUT list
A26: 45988 | B26: Mauritius Telecom Connect | C26: Other | D26: Other | E26: Petty Cash | F26: Cash | G26: 411 | H26: Petty Cash | I26: No | K26: =IF(OR(G26="",I26=""),"",IF(UPPER(I26)="YES",G26*J26,0)) -> 0 | L26: =IF(G26="","",G26+K26) -> 411 | N26: Pending | P26: Source: Petty Cash OUT list
A27: 45988 | B27: Mauritius Telecom Connect | C27: Food | D27: Food | E27: Petty Cash | F27: Cash | G27: 460 | H27: Petty Cash | I27: Yes | J27: 0.15 | K27: =IF(OR(G27="",I27=""),"",IF(UPPER(I27)="YES",G27*J27,0)) -> 69 | L27: =IF(G27="","",G27-K27) -> 391 | N27: Pending | P27: Source: Petty Cash OUT list
A28: 45988 | B28: Mauritius Telecom Connect | C28: Others | D28: Other | E28: Petty Cash | F28: Cash | G28: 2070 | H28: Petty Cash | I28: No | K28: =IF(OR(G28="",I28=""),"",IF(UPPER(I28)="YES",G28*J28,0)) -> 0 | L28: =IF(G28="","",G28+K28) -> 2070 | N28: Pending | P28: Source: Petty Cash OUT list
A29: 45988 | B29: Mauritius Telecom Connect | C29: Groceries | D29: Food | E29: Petty Cash | F29: Cash | G29: 2900 | H29: Petty Cash | I29: Yes | J29: 0.15 | K29: =IF(OR(G29="",I29=""),"",IF(UPPER(I29)="YES",G29*J29,0)) -> 435 | L29: =IF(G29="","",G29-K29) -> 2465 | N29: Pending | P29: Source: Petty Cash OUT list
A30: 45988 | B30: Mauritius Telecom Connect | C30: Food | D30: Food | E30: Petty Cash | F30: Cash | G30: 477 | H30: Petty Cash | I30: Yes | J30: 0.15 | K30: =IF(OR(G30="",I30=""),"",IF(UPPER(I30)="YES",G30*J30,0)) -> 71.55 | L30: =IF(G30="","",G30-K30) -> 405.45 | N30: Pending | P30: Source: Petty Cash OUT list
A31: 45989 | B31: Mauritius Telecom Connect | C31: Food | D31: Food | E31: Petty Cash | F31: Cash | G31: 1800 | H31: Petty Cash | I31: Yes | J31: 0.15 | K31: =IF(OR(G31="",I31=""),"",IF(UPPER(I31)="YES",G31*J31,0)) -> 270 | L31: =IF(G31="","",G31-K31) -> 1530 | N31: Pending | P31: Source: Petty Cash OUT list
A32: 45989 | B32: Mauritius Telecom Connect | C32: AI BANANA | D32: Other | E32: Petty Cash | F32: Cash | G32: 3095 | H32: Petty Cash | I32: No | K32: =IF(OR(G32="",I32=""),"",IF(UPPER(I32)="YES",G32*J32,0)) -> 0 | L32: =IF(G32="","",G32+K32) -> 3095 | N32: Pending | P32: Source: Petty Cash OUT list
A33: 45989 | B33: Mauritius Telecom Connect | C33: Food | D33: Food | E33: Petty Cash | F33: Cash | G33: 940 | H33: Petty Cash | I33: Yes | J33: 0.15 | K33: =IF(OR(G33="",I33=""),"",IF(UPPER(I33)="YES",G33*J33,0)) -> 141 | L33: =IF(G33="","",G33-K33) -> 799 | N33: Pending | P33: Source: Petty Cash OUT list
A34: 45990 | B34: Mauritius Telecom Connect | C34: Food | D34: Food | E34: Petty Cash | F34: Cash | G34: 1590 | H34: Petty Cash | I34: Yes | J34: 0.15 | K34: =IF(OR(G34="",I34=""),"",IF(UPPER(I34)="YES",G34*J34,0)) -> 238.5 | L34: =IF(G34="","",G34-K34) -> 1351.5 | N34: Pending | P34: Source: Petty Cash OUT list
A35: 45991 | B35: Mauritius Telecom Connect | C35: Food | D35: Food | E35: Petty Cash | F35: Cash | G35: 440 | H35: Petty Cash | I35: Yes | J35: 0.15 | K35: =IF(OR(G35="",I35=""),"",IF(UPPER(I35)="YES",G35*J35,0)) -> 66 | L35: =IF(G35="","",G35-K35) -> 374 | N35: Pending | P35: Source: Petty Cash OUT list
A36: 45991 | B36: Mauritius Telecom Connect | C36: other | D36: Other | E36: Petty Cash | F36: Cash | G36: 145 | H36: Petty Cash | I36: No | K36: =IF(OR(G36="",I36=""),"",IF(UPPER(I36)="YES",G36*J36,0)) -> 0 | L36: =IF(G36="","",G36+K36) -> 145 | N36: Pending | P36: Source: Petty Cash OUT list
A37: 45991 | B37: Mauritius Telecom Connect | C37: Food | D37: Food | E37: Petty Cash | F37: Cash | G37: 2500 | H37: Petty Cash | I37: Yes | J37: 0.15 | K37: =IF(OR(G37="",I37=""),"",IF(UPPER(I37)="YES",G37*J37,0)) -> 375 | L37: =IF(G37="","",G37-K37) -> 2125 | N37: Pending | P37: Source: Petty Cash OUT list
A38: 45992 | B38: Mauritius Telecom Connect | C38: Drink | D38: Food | E38: Petty Cash | F38: Cash | G38: 1000 | H38: Petty Cash | I38: Yes | J38: 0.15 | K38: =IF(OR(G38="",I38=""),"",IF(UPPER(I38)="YES",G38*J38,0)) -> 150 | L38: =IF(G38="","",G38-K38) -> 850 | N38: Pending | P38: Source: Petty Cash OUT list
A39: 45992 | B39: Mauritius Telecom Connect | C39: Food Eric | D39: Food | E39: Petty Cash | F39: Cash | G39: 440 | H39: Petty Cash | I39: Yes | J39: 0.15 | K39: =IF(OR(G39="",I39=""),"",IF(UPPER(I39)="YES",G39*J39,0)) -> 66 | L39: =IF(G39="","",G39-K39) -> 374 | N39: Pending | P39: Source: Petty Cash OUT list
A40: 45993 | B40: Mauritius Telecom Connect | C40: other | D40: Other | E40: Petty Cash | F40: Cash | G40: 2775 | H40: Petty Cash | I40: No | K40: =IF(OR(G40="",I40=""),"",IF(UPPER(I40)="YES",G40*J40,0)) -> 0 | L40: =IF(G40="","",G40+K40) -> 2775 | N40: Pending | P40: Source: Petty Cash OUT list
...

Sheet Cash
A1: Date | B1: Project | C1: Person | D1: Description | E1: Category | F1: Amount (Rs) | G1: Type | H1: Status | I1: Reimbursed Date | J1: Linked Expense Ref | K1: Notes
B2: Mauritius Telecom Connect | C2: Harsh | D2: Fuel / Food / Misc | E2: Food | F2: 7800 | G2: Advance | H2: Owed
B3: Mauritius Telecom Connect | C3: Avneesh | D3: Food / Misc | E3: Food | F3: 8817.55 | G3: Advance | H3: Owed
B4: Mauritius Telecom Connect | C4: Williams | D4: Food / Misc | E4: Food | F4: 200 | G4: Advance | H4: Owed

Sheet Dashboard
A1: PROJECT FINANCIAL DASHBOARD (MUR)
A3: Project: | B3: Mauritius Telecom Connect | C3: Month (YYYY-MM):
A4: FINAL BREAKDOWN — Income vs Expenses, Who Paid What
A6: Total Income (Approved Quote) | B6: =Approved_KRIS!B29 -> 1600500 | F6: DISCOUNT (Kris) | G6: =Approved_KRIS!B26 -> 80000
A7: Total Expenses (Excl VAT) | B7: =E17+E35 -> 1030841.3 | E7: Amount (Rs) | F7: Agency Fee (10%) | G7: =Approved_KRIS!B28 -> 145500
A8: VAT on Expenses | B8: =IF($B$3="","",SUMIFS(tblExpenses[VAT Amount (Rs)],tblExpenses[Project],$B$3)) -> 9249.4935 | E8: =IF($B$3="","",IF(SUMIFS(tblExpenses[Total excl VAT (Rs)],tblExpenses[Project],$B$3,tblExpenses[Paid By],$D8)=0,"",SUMIFS(tblExpenses[Total excl VAT (Rs)],tblExpenses[Project],$B$3,tblExpenses[Paid By],$D8))) | F8: Income excl VAT | G8: =Approved_KRIS!B29 -> 1600500
A9: Total Expenses (Incl VAT) | B9: =B7*15% -> 154626.2 | D9: Avneesh | E9: =IF($B$3="","",IF(SUMIFS(tblExpenses[Total excl VAT (Rs)],tblExpenses[Project],$B$3,tblExpenses[Paid By],$D9)=0,"",SUMIFS(tblExpenses[Total excl VAT (Rs)],tblExpenses[Project],$B$3,tblExpenses[Paid By],$D9))) -> 7494.9175 | F9: VAT on Total Income | G9: =Approved_KRIS!B30 -> 240075
A10: Net Result (Income - Expenses incl VAT) | B10: =IF(OR(B6="",B9=""),"",B6-B9) -> 1445873.8 | D10: Long | E10: =IF($B$3="","",IF(SUMIFS(tblExpenses[Total excl VAT (Rs)],tblExpenses[Project],$B$3,tblExpenses[Paid By],$D10)=0,"",SUMIFS(tblExpenses[Total excl VAT (Rs)],tblExpenses[Project],$B$3,tblExpenses[Paid By],$D10))) | F10: Income incl VAT | G10: =Approved_KRIS!B31 -> 1840575
A11: Gross Margin % | B11: =IF(B6="","",IF(B6=0,"",B10/B6)) -> 0.90338882 | D11: Williams | E11: =IF($B$3="","",IF(SUMIFS(tblExpenses[Total excl VAT (Rs)],tblExpenses[Project],$B$3,tblExpenses[Paid By],$D11)=0,"",SUMIFS(tblExpenses[Total excl VAT (Rs)],tblExpenses[Project],$B$3,tblExpenses[Paid By],$D11)))
A12: Total Cash Owed (Advances not reimbursed) | B12: =IF($B$3="","",SUMIFS(tblCash[Amount (Rs)],tblCash[Project],$B$3,tblCash[Status],"Owed")) -> 16817.55 | D12: Laura | E12: =IF($B$3="","",IF(SUMIFS(tblExpenses[Total excl VAT (Rs)],tblExpenses[Project],$B$3,tblExpenses[Paid By],$D12)=0,"",SUMIFS(tblExpenses[Total excl VAT (Rs)],tblExpenses[Project],$B$3,tblExpenses[Paid By],$D12)))
A13: Description | B13: Paid By | C13: Total (Rs) | D13: Other | E13: =IF($B$3="","",IF(SUMIFS(tblExpenses[Total excl VAT (Rs)],tblExpenses[Project],$B$3,tblExpenses[Paid By],$D13)=0,"",SUMIFS(tblExpenses[Total excl VAT (Rs)],tblExpenses[Project],$B$3,tblExpenses[Paid By],$D13)))
A14: (Tip) For detailed top-lines, sort the Expenses table by Total Incl VAT. | D14: Harsh | E14: =IF($B$3="","",IF(SUMIFS(tblExpenses[Total excl VAT (Rs)],tblExpenses[Project],$B$3,tblExpenses[Paid By],$D14)=0,"",SUMIFS(tblExpenses[Total excl VAT (Rs)],tblExpenses[Project],$B$3,tblExpenses[Paid By],$D14))) -> 12000
D15: Kunal | E15: =IF($B$3="","",IF(SUMIFS(tblExpenses[Total excl VAT (Rs)],tblExpenses[Project],$B$3,tblExpenses[Paid By],$D15)=0,"",SUMIFS(tblExpenses[Total excl VAT (Rs)],tblExpenses[Project],$B$3,tblExpenses[Paid By],$D15))) -> 42753.15
A16: INCOME BY CATEGORY | D16: Petty Cash | E16: =IF($B$3="","",IF(SUMIFS(tblExpenses[Total excl VAT (Rs)],tblExpenses[Project],$B$3,tblExpenses[Paid By],$D16)=0,"",SUMIFS(tblExpenses[Total excl VAT (Rs)],tblExpenses[Project],$B$3,tblExpenses[Paid By],$D16))) -> 53352.439
A17: Category | B17: Amount (Rs) | D17: TOTAL | E17: =SUM(E9:E16) -> 115600.51
A18: Creative Direction | B18: =IF($B$3="","",IF(SUMIFS(tblRevenue[Line Total (Rs)],tblRevenue[Project],$B$3,tblRevenue[Category],$A18)=0,"",SUMIFS(tblRevenue[Line Total (Rs)],tblRevenue[Project],$B$3,tblRevenue[Category],$A18))) -> 300000
A19: Design | B19: =IF($B$3="","",IF(SUMIFS(tblRevenue[Line Total (Rs)],tblRevenue[Project],$B$3,tblRevenue[Category],$A19)=0,"",SUMIFS(tblRevenue[Line Total (Rs)],tblRevenue[Project],$B$3,tblRevenue[Category],$A19))) -> 525000 | D19: EXPENSES BY CATEGORY | E19: =IF($B$3="","",IF(SUMIFS(tblExpenses[Total excl VAT (Rs)],tblExpenses[Project],$B$3,tblExpenses[Paid By],$D19)=0,"",SUMIFS(tblExpenses[Total excl VAT (Rs)],tblExpenses[Project],$B$3,tblExpenses[Paid By],$D19)))
A20: Video | B20: =IF($B$3="","",IF(SUMIFS(tblRevenue[Line Total (Rs)],tblRevenue[Project],$B$3,tblRevenue[Category],$A20)=0,"",SUMIFS(tblRevenue[Line Total (Rs)],tblRevenue[Project],$B$3,tblRevenue[Category],$A20))) -> 320000 | D20: Category | E20: =IF($B$3="","",IF(SUMIFS(tblExpenses[Total excl VAT (Rs)],tblExpenses[Project],$B$3,tblExpenses[Paid By],$D20)=0,"",SUMIFS(tblExpenses[Total excl VAT (Rs)],tblExpenses[Project],$B$3,tblExpenses[Paid By],$D20)))
A21: Tech/AV | B21: =IF($B$3="","",IF(SUMIFS(tblRevenue[Line Total (Rs)],tblRevenue[Project],$B$3,tblRevenue[Category],$A21)=0,"",SUMIFS(tblRevenue[Line Total (Rs)],tblRevenue[Project],$B$3,tblRevenue[Category],$A21))) -> 70000 | D21: Creative Direction | E21: =IF($B$3="","",IF(SUMIFS(tblExpenses[Total excl VAT (Rs)],tblExpenses[Project],$B$3,tblExpenses[Category],$D21)=0,"",SUMIFS(tblExpenses[Total excl VAT (Rs)],tblExpenses[Project],$B$3,tblExpenses[Category],$D21))) -> 349000
A22: Scenography | B22: =IF($B$3="","",IF(SUMIFS(tblRevenue[Line Total (Rs)],tblRevenue[Project],$B$3,tblRevenue[Category],$A22)=0,"",SUMIFS(tblRevenue[Line Total (Rs)],tblRevenue[Project],$B$3,tblRevenue[Category],$A22))) | D22: Design | E22: =IF($B$3="","",IF(SUMIFS(tblExpenses[Total excl VAT (Rs)],tblExpenses[Project],$B$3,tblExpenses[Category],$D22)=0,"",SUMIFS(tblExpenses[Total excl VAT (Rs)],tblExpenses[Project],$B$3,tblExpenses[Category],$D22))) -> 120000
A23: Production | B23: 130000 | D23: Video | E23: =IF($B$3="","",IF(SUMIFS(tblExpenses[Total excl VAT (Rs)],tblExpenses[Project],$B$3,tblExpenses[Category],$D23)=0,"",SUMIFS(tblExpenses[Total excl VAT (Rs)],tblExpenses[Project],$B$3,tblExpenses[Category],$D23))) -> 285000
A24: Travel | B24: =IF($B$3="","",IF(SUMIFS(tblRevenue[Line Total (Rs)],tblRevenue[Project],$B$3,tblRevenue[Category],$A24)=0,"",SUMIFS(tblRevenue[Line Total (Rs)],tblRevenue[Project],$B$3,tblRevenue[Category],$A24))) | D24: Tech/AV | E24: =IF($B$3="","",IF(SUMIFS(tblExpenses[Total excl VAT (Rs)],tblExpenses[Project],$B$3,tblExpenses[Category],$D24)=0,"",SUMIFS(tblExpenses[Total excl VAT (Rs)],tblExpenses[Project],$B$3,tblExpenses[Category],$D24))) -> 810
A25: Food | B25: =IF($B$3="","",IF(SUMIFS(tblRevenue[Line Total (Rs)],tblRevenue[Project],$B$3,tblRevenue[Category],$A25)=0,"",SUMIFS(tblRevenue[Line Total (Rs)],tblRevenue[Project],$B$3,tblRevenue[Category],$A25))) -> 120000 | D25: Scenography | E25: =IF($B$3="","",IF(SUMIFS(tblExpenses[Total excl VAT (Rs)],tblExpenses[Project],$B$3,tblExpenses[Category],$D25)=0,"",SUMIFS(tblExpenses[Total excl VAT (Rs)],tblExpenses[Project],$B$3,tblExpenses[Category],$D25)))
A26: TOTAL | B26: =SUM(B18:B25) -> 1465000 | D26: Production | E26: =IF($B$3="","",IF(SUMIFS(tblExpenses[Total excl VAT (Rs)],tblExpenses[Project],$B$3,tblExpenses[Category],$D26)=0,"",SUMIFS(tblExpenses[Total excl VAT (Rs)],tblExpenses[Project],$B$3,tblExpenses[Category],$D26))) -> 70000
D27: Travel | E27: =IF($B$3="","",IF(SUMIFS(tblExpenses[Total excl VAT (Rs)],tblExpenses[Project],$B$3,tblExpenses[Category],$D27)=0,"",SUMIFS(tblExpenses[Total excl VAT (Rs)],tblExpenses[Project],$B$3,tblExpenses[Category],$D27)))
D28: Food | E28: =IF($B$3="","",IF(SUMIFS(tblExpenses[Total excl VAT (Rs)],tblExpenses[Project],$B$3,tblExpenses[Category],$D28)=0,"",SUMIFS(tblExpenses[Total excl VAT (Rs)],tblExpenses[Project],$B$3,tblExpenses[Category],$D28))) -> 52413.797
D29: Transport | E29: =IF($B$3="","",IF(SUMIFS(tblExpenses[Total excl VAT (Rs)],tblExpenses[Project],$B$3,tblExpenses[Category],$D29)=0,"",SUMIFS(tblExpenses[Total excl VAT (Rs)],tblExpenses[Project],$B$3,tblExpenses[Category],$D29))) -> 38000
D30: Accommodation | E30: =IF($B$3="","",IF(SUMIFS(tblExpenses[Total excl VAT (Rs)],tblExpenses[Project],$B$3,tblExpenses[Category],$D30)=0,"",SUMIFS(tblExpenses[Total excl VAT (Rs)],tblExpenses[Project],$B$3,tblExpenses[Category],$D30)))
D31: Printing | E31: =IF($B$3="","",IF(SUMIFS(tblExpenses[Total excl VAT (Rs)],tblExpenses[Project],$B$3,tblExpenses[Category],$D31)=0,"",SUMIFS(tblExpenses[Total excl VAT (Rs)],tblExpenses[Project],$B$3,tblExpenses[Category],$D31)))
D32: Rentals | E32: =IF($B$3="","",IF(SUMIFS(tblExpenses[Total excl VAT (Rs)],tblExpenses[Project],$B$3,tblExpenses[Category],$D32)=0,"",SUMIFS(tblExpenses[Total excl VAT (Rs)],tblExpenses[Project],$B$3,tblExpenses[Category],$D32)))
D33: Discount
D34: Subotal | E34: =SUM(E21:E33) -> 915223.8
A35: If any totals show blank, check the Project name matches exactly in Revenue/Expenses/Cash tables. | B35: =IF($B$3="","",IF(SUMIFS(tblRevenue[Line Total (Rs)],tblRevenue[Project],$B$3,tblRevenue[Category],$A35)=0,"",SUMIFS(tblRevenue[Line Total (Rs)],tblRevenue[Project],$B$3,tblRevenue[Category],$A35))) | D35: TOTAL | E35: =17+E34 -> 915240.8
A40: How to use:
A41: 1) Fill Revenue / Expenses / Cash tables. 2) Type the project name in Dashboard!B3 to see totals.
A44: Expenses by Paid By
A45: Paid By | B45: Amount (Rs)
A46: ë | B46: =IF($B$3="","",SUMIFS(tblExpenses[Total excl VAT (Rs)],tblExpenses[Project],$B$3,tblExpenses[Paid By],$A46)) -> 873500
A47: Avneesh | B47: =IF($B$3="","",SUMIFS(tblExpenses[Total excl VAT (Rs)],tblExpenses[Project],$B$3,tblExpenses[Paid By],$A47)) -> 7494.9175
A48: Long | B48: =IF($B$3="","",SUMIFS(tblExpenses[Total excl VAT (Rs)],tblExpenses[Project],$B$3,tblExpenses[Paid By],$A48)) -> 0
...
